Workbook

Sheet Leia-me
B1: Indicadores dos municípios de São Paulo: Entregável de amostra
B3: O que é
B4: Uma planilha que junta, para os 645 municípios de SP, oito indicadores de finanças, educação, saúde e economia, de 2015 a 2025, e compara cada município com os de mesmo porte. Tem ainda uma previsão simples da receita, com a incerteza à vista.
B6: O que não é
B7: Não é trabalho feito para um Cliente nem avaliação de nenhuma prefeitura. É uma amostra feita com dado público, para mostrar como a entrega chega às mãos de quem compra. Nenhum número aqui é resultado de Cliente.
B9: Como usar
B10: 1) Vá à aba "Painel". 2) Escolha o município na célula amarela. 3) Leia a tabela, os gráficos e, em "Previsão", a projeção da receita. As abas "Dados", "Referência", "Previsões" e "Municípios" guardam os números de origem; as demais abas são fórmulas sobre elas.
B12: Como conferir um número
B13: Cada fórmula aponta para a aba "Dados" ou "Referência". Cada linha de "Dados" vem do arquivo indicadores_longo.csv, que as consultas SQL do repositório geram. O README do repositório explica, indicador por indicador, o caminho do número bruto até a célula.
B15: Como ler a comparação
B16: A mediana é a dos municípios do mesmo porte (Censo 2022) no mesmo ano. A posição vai de 0% (menor valor da faixa) a 100% (maior). Estar acima ou abaixo não é bom nem ruim por si: depende de escolhas e de contexto do município.
B18: Cuidados
... B25: Tesouro Nacional (Siconfi), IBGE, INEP e DataSUS. Licenças e como cada uma foi verificada: aba "Fontes e licenças".

Sheet Painel
B1: Indicadores dos municípios de São Paulo
B2: Escolha um município na célula amarela. Tudo abaixo e nas abas "Tabela do município" e "Previsão" se recalcula.
B4: Município (escolha na lista) | C4: Ibirá
B5: Código IBGE | C5: =INDEX('Municípios'!$A$2:$A$646,MATCH($C$4,'Municípios'!$B$2:$B$646,0)) -> 3519402
B6: Faixa de porte (municípios parecidos) | C6: =INDEX('Municípios'!$C$2:$C$646,MATCH($C$4,'Municípios'!$B$2:$B$646,0)) -> 3. De 10 a 20 mil
B7: Municípios na faixa | C7: =COUNTIF('Municípios'!$C$2:$C$646,$C$6) -> 120
B8: População (Censo 2022) | C8: =INDEX('Municípios'!$E$2:$E$646,MATCH($C$4,'Municípios'!$B$2:$B$646,0)) -> 11690
B9: Região geográfica imediata (IBGE) | C9: =INDEX('Municípios'!$D$2:$D$646,MATCH($C$4,'Municípios'!$B$2:$B$646,0)) -> São José do Rio Preto
B11: Último valor de cada indicador, comparado com os municípios da faixa
B12: Indicador | C12: Unidade | D12: Último ano com dado | E12: Valor do município | F12: Mediana da faixa | G12: Diferença para a mediana | H12: Posição na faixa (0% a 100%)
B13: Receita corrente por habitante | C13: R$ por habitante, a preços de 2025 | D13: =IFERROR(SUMPRODUCT(MAX(ISNUMBER('Tabela do município'!$C$10:$M$10)*'Tabela do município'!$C$8:$M$8)),"n.d.") -> 2025 | E13: =IFERROR(INDEX('Tabela do município'!$C$10:$M$10,MATCH(D13,'Tabela do município'!$C$8:$M$8,0)),"n.d.") -> 6414.1779 | F13: =IFERROR(INDEX('Referência'!$H$2:$H$554,MATCH($C$6&"|"&D13&"|receita_pc",'Referência'!$A$2:$A$554,0)),"n.d.") -> 6742.3652 | G13: =IF(AND(ISNUMBER(E13),ISNUMBER(F13)),E13/F13-1,"n.d.") -> -0.048675394 | H13: =IFERROR(COUNTIFS('Dados'!$E$2:$E$7096,$C$6,'Dados'!$D$2:$D$7096,D13,'Dados'!$F$2:$F$7096,"<"&E13)/(INDEX('Referência'!$E$2:$E$554,MATCH($C$6&"|"&D13&"|receita_pc",'Referência'!$A$2:$A$554,0))-1),"n.d.") -> 0.3697479
B14: Dependência de transferências | C14: % da receita corrente | D14: =IFERROR(SUMPRODUCT(MAX(ISNUMBER('Tabela do município'!$C$16:$M$16)*'Tabela do município'!$C$8:$M$8)),"n.d.") -> 2025 | E14: =IFERROR(INDEX('Tabela do município'!$C$16:$M$16,MATCH(D14,'Tabela do município'!$C$8:$M$8,0)),"n.d.") -> 81.244751 | F14: =IFERROR(INDEX('Referência'!$H$2:$H$554,MATCH($C$6&"|"&D14&"|dependencia_transf",'Referência'!$A$2:$A$554,0)),"n.d.") -> 82.033032 | G14: =IF(AND(ISNUMBER(E14),ISNUMBER(F14)),E14/F14-1,"n.d.") -> -0.0096093164 | H14: =IFERROR(COUNTIFS('Dados'!$E$2:$E$7096,$C$6,'Dados'!$D$2:$D$7096,D14,'Dados'!$G$2:$G$7096,"<"&E14)/(INDEX('Referência'!$E$2:$E$554,MATCH($C$6&"|"&D14&"|dependencia_transf",'Referência'!$A$2:$A$554,0))-1),"n.d.") -> 0.41176471
B15: Despesa com saúde por habitante | C15: R$ por habitante, a preços de 2025 | D15: =IFERROR(SUMPRODUCT(MAX(ISNUMBER('Tabela do município'!$C$22:$M$22)*'Tabela do município'!$C$8:$M$8)),"n.d.") -> 2025 | E15: =IFERROR(INDEX('Tabela do município'!$C$22:$M$22,MATCH(D15,'Tabela do município'!$C$8:$M$8,0)),"n.d.") -> 2245.8282 | F15: =IFERROR(INDEX('Referência'!$H$2:$H$554,MATCH($C$6&"|"&D15&"|saude_pc",'Referência'!$A$2:$A$554,0)),"n.d.") -> 1892.7691 | G15: =IF(AND(ISNUMBER(E15),ISNUMBER(F15)),E15/F15-1,"n.d.") -> 0.18653051 | H15: =IFERROR(COUNTIFS('Dados'!$E$2:$E$7096,$C$6,'Dados'!$D$2:$D$7096,D15,'Dados'!$H$2:$H$7096,"<"&E15)/(INDEX('Referência'!$E$2:$E$554,MATCH($C$6&"|"&D15&"|saude_pc",'Referência'!$A$2:$A$554,0))-1),"n.d.") -> 0.78991597
B16: Despesa com educação por habitante | C16: R$ por habitante, a preços de 2025 | D16: =IFERROR(SUMPRODUCT(MAX(ISNUMBER('Tabela do município'!$C$28:$M$28)*'Tabela do município'!$C$8:$M$8)),"n.d.") -> 2025 | E16: =IFERROR(INDEX('Tabela do município'!$C$28:$M$28,MATCH(D16,'Tabela do município'!$C$8:$M$8,0)),"n.d.") -> 1914.6131 | F16: =IFERROR(INDEX('Referência'!$H$2:$H$554,MATCH($C$6&"|"&D16&"|educacao_pc",'Referência'!$A$2:$A$554,0)),"n.d.") -> 2060.5831 | G16: =IF(AND(ISNUMBER(E16),ISNUMBER(F16)),E16/F16-1,"n.d.") -> -0.070839202 | H16: =IFERROR(COUNTIFS('Dados'!$E$2:$E$7096,$C$6,'Dados'!$D$2:$D$7096,D16,'Dados'!$I$2:$I$7096,"<"&E16)/(INDEX('Referência'!$E$2:$E$554,MATCH($C$6&"|"&D16&"|educacao_pc",'Referência'!$A$2:$A$554,0))-1),"n.d.") -> 0.38655462
B17: PIB por habitante | C17: R$ por habitante, a preços de 2025 | D17: =IFERROR(SUMPRODUCT(MAX(ISNUMBER('Tabela do município'!$C$34:$M$34)*'Tabela do município'!$C$8:$M$8)),"n.d.") -> 2023 | E17: =IFERROR(INDEX('Tabela do município'!$C$34:$M$34,MATCH(D17,'Tabela do município'!$C$8:$M$8,0)),"n.d.") -> 38802.657 | F17: =IFERROR(INDEX('Referência'!$H$2:$H$554,MATCH($C$6&"|"&D17&"|pib_pc",'Referência'!$A$2:$A$554,0)),"n.d.") -> 42511.916 | G17: =IF(AND(ISNUMBER(E17),ISNUMBER(F17)),E17/F17-1,"n.d.") -> -0.087252229 | H17: =IFERROR(COUNTIFS('Dados'!$E$2:$E$7096,$C$6,'Dados'!$D$2:$D$7096,D17,'Dados'!$J$2:$J$7096,"<"&E17)/(INDEX('Referência'!$E$2:$E$554,MATCH($C$6&"|"&D17&"|pib_pc",'Referência'!$A$2:$A$554,0))-1),"n.d.") -> 0.43697479
B18: Ideb dos anos iniciais, rede municipal | C18: nota de 0 a 10 | D18: =IFERROR(SUMPRODUCT(MAX(ISNUMBER('Tabela do município'!$C$40:$M$40)*'Tabela do município'!$C$8:$M$8)),"n.d.") -> 2023 | E18: =IFERROR(INDEX('Tabela do município'!$C$40:$M$40,MATCH(D18,'Tabela do município'!$C$8:$M$8,0)),"n.d.") -> 7.3 | F18: =IFERROR(INDEX('Referência'!$H$2:$H$554,MATCH($C$6&"|"&D18&"|ideb",'Referência'!$A$2:$A$554,0)),"n.d.") -> 6.3 | G18: =IF(AND(ISNUMBER(E18),ISNUMBER(F18)),E18/F18-1,"n.d.") -> 0.15873016 | H18: =IFERROR(COUNTIFS('Dados'!$E$2:$E$7096,$C$6,'Dados'!$D$2:$D$7096,D18,'Dados'!$K$2:$K$7096,"<"&E18)/(INDEX('Referência'!$E$2:$E$554,MATCH($C$6&"|"&D18&"|ideb",'Referência'!$A$2:$A$554,0))-1),"n.d.") -> 0.92307692
B19: Nascidos de mães com 7 ou mais consultas de pré-natal | C19: % dos nascidos vivos com número de consultas informado | D19: =IFERROR(SUMPRODUCT(MAX(ISNUMBER('Tabela do município'!$C$46:$M$46)*'Tabela do município'!$C$8:$M$8)),"n.d.") -> 2024 | E19: =IFERROR(INDEX('Tabela do município'!$C$46:$M$46,MATCH(D19,'Tabela do município'!$C$8:$M$8,0)),"n.d.") -> 88.571429 | F19: =IFERROR(INDEX('Referência'!$H$2:$H$554,MATCH($C$6&"|"&D19&"|pre_natal_7mais",'Referência'!$A$2:$A$554,0)),"n.d.") -> 87.380573 | G19: =IF(AND(ISNUMBER(E19),ISNUMBER(F19)),E19/F19-1,"n.d.") -> 0.013628376 | H19: =IFERROR(COUNTIFS('Dados'!$E$2:$E$7096,$C$6,'Dados'!$D$2:$D$7096,D19,'Dados'!$L$2:$L$7096,"<"&E19)/(INDEX('Referência'!$E$2:$E$554,MATCH($C$6&"|"&D19&"|pre_natal_7mais",'Referência'!$A$2:$A$554,0))-1),"n.d.") -> 0.57983193
B21: Como ler: a mediana é a do grupo de municípios do mesmo porte (Censo 2022) no mesmo ano. "Posição" diz quantos municípios da faixa têm valor menor: 0% é o menor valor, 100% é o maior. Estar acima ou abaixo da mediana não é, por si, bom nem ruim: a gestão do município pode ter razão para o desvio.

Sheet Tabela do município
A1: Tabela do município
A2: Município (escolhido na aba Painel) | B2: =Painel!$C$4 -> Ibirá
A3: Código IBGE | B3: =Painel!$C$5 -> 3519402
A4: Faixa de porte | B4: =Painel!$C$6 -> 3. De 10 a 20 mil
A5: As linhas "n.d." são anos em que a fonte não publica ou o município não declarou. Nenhum valor foi estimado.
A8: Indicador | B8: Linha | C8: 2015 | D8: 2016 | E8: 2017 | F8: 2018 | G8: 2019 | H8: 2020 | I8: 2021 | J8: 2022 | K8: 2023 | L8: 2024 | M8: 2025
A10: Receita corrente por habitante | B10: Valor do município | C10: =IFERROR(INDEX('Dados'!$F$2:$F$7096,MATCH($B$3&"|"&C$8,'Dados'!$A$2:$A$7096,0)),"n.d.") -> 5045.6732 | D10: =IFERROR(INDEX('Dados'!$F$2:$F$7096,MATCH($B$3&"|"&D$8,'Dados'!$A$2:$A$7096,0)),"n.d.") -> 4939.5866 | E10: =IFERROR(INDEX('Dados'!$F$2:$F$7096,MATCH($B$3&"|"&E$8,'Dados'!$A$2:$A$7096,0)),"n.d.") -> 4423.0264 | F10: =IFERROR(INDEX('Dados'!$F$2:$F$7096,MATCH($B$3&"|"&F$8,'Dados'!$A$2:$A$7096,0)),"n.d.") -> 4407.8775 | G10: =IFERROR(INDEX('Dados'!$F$2:$F$7096,MATCH($B$3&"|"&G$8,'Dados'!$A$2:$A$7096,0)),"n.d.") -> 4529.9706 | H10: =IFERROR(INDEX('Dados'!$F$2:$F$7096,MATCH($B$3&"|"&H$8,'Dados'!$A$2:$A$7096,0)),"n.d.") -> 4764.5181 | I10: =IFERROR(INDEX('Dados'!$F$2:$F$7096,MATCH($B$3&"|"&I$8,'Dados'!$A$2:$A$7096,0)),"n.d.") -> 4859.3721 | J10: =IFERROR(INDEX('Dados'!$F$2:$F$7096,MATCH($B$3&"|"&J$8,'Dados'!$A$2:$A$7096,0)),"n.d.") -> 5671.5544 | ... M10: =IFERROR(INDEX('Dados'!$F$2:$F$7096,MATCH($B$3&"|"&M$8,'Dados'!$A$2:$A$7096,0)),"n.d.") -> 6414.1779
B11: Mediana da faixa | C11: =IFERROR(INDEX('Referência'!$H$2:$H$554,MATCH($B$4&"|"&C$8&"|receita_pc",'Referência'!$A$2:$A$554,0)),"n.d.") -> 4329.0905 | D11: =IFERROR(INDEX('Referência'!$H$2:$H$554,MATCH($B$4&"|"&D$8&"|receita_pc",'Referência'!$A$2:$A$554,0)),"n.d.") -> 4326.2518 | E11: =IFERROR(INDEX('Referência'!$H$2:$H$554,MATCH($B$4&"|"&E$8&"|receita_pc",'Referência'!$A$2:$A$554,0)),"n.d.") -> 4209.9006 | F11: =IFERROR(INDEX('Referência'!$H$2:$H$554,MATCH($B$4&"|"&F$8&"|receita_pc",'Referência'!$A$2:$A$554,0)),"n.d.") -> 4395.399 | G11: =IFERROR(INDEX('Referência'!$H$2:$H$554,MATCH($B$4&"|"&G$8&"|receita_pc",'Referência'!$A$2:$A$554,0)),"n.d.") -> 4530.5635 | H11: =IFERROR(INDEX('Referência'!$H$2:$H$554,MATCH($B$4&"|"&H$8&"|receita_pc",'Referência'!$A$2:$A$554,0)),"n.d.") -> 4707.0642 | I11: =IFERROR(INDEX('Referência'!$H$2:$H$554,MATCH($B$4&"|"&I$8&"|receita_pc",'Referência'!$A$2:$A$554,0)),"n.d.") -> 4997.4084 | J11: =IFERROR(INDEX('Referência'!$H$2:$H$554,MATCH($B$4&"|"&J$8&"|receita_pc",'Referência'!$A$2:$A$554,0)),"n.d.") -> 5956.9405 | ... M11: =IFERROR(INDEX('Referência'!$H$2:$H$554,MATCH($B$4&"|"&M$8&"|receita_pc",'Referência'!$A$2:$A$554,0)),"n.d.") -> 6742.3652
B12: 1º quartil da faixa | C12: =IFERROR(INDEX('Referência'!$G$2:$G$554,MATCH($B$4&"|"&C$8&"|receita_pc",'Referência'!$A$2:$A$554,0)),"n.d.") -> 3837.6036 | D12: =IFERROR(INDEX('Referência'!$G$2:$G$554,MATCH($B$4&"|"&D$8&"|receita_pc",'Referência'!$A$2:$A$554,0)),"n.d.") -> 3841.4824 | E12: =IFERROR(INDEX('Referência'!$G$2:$G$554,MATCH($B$4&"|"&E$8&"|receita_pc",'Referência'!$A$2:$A$554,0)),"n.d.") -> 3791.0285 | F12: =IFERROR(INDEX('Referência'!$G$2:$G$554,MATCH($B$4&"|"&F$8&"|receita_pc",'Referência'!$A$2:$A$554,0)),"n.d.") -> 3915.0146 | G12: =IFERROR(INDEX('Referência'!$G$2:$G$554,MATCH($B$4&"|"&G$8&"|receita_pc",'Referência'!$A$2:$A$554,0)),"n.d.") -> 3990.5777 | H12: =IFERROR(INDEX('Referência'!$G$2:$G$554,MATCH($B$4&"|"&H$8&"|receita_pc",'Referência'!$A$2:$A$554,0)),"n.d.") -> 4168.6221 | I12: =IFERROR(INDEX('Referência'!$G$2:$G$554,MATCH($B$4&"|"&I$8&"|receita_pc",'Referência'!$A$2:$A$554,0)),"n.d.") -> 4460.0029 | J12: =IFERROR(INDEX('Referência'!$G$2:$G$554,MATCH($B$4&"|"&J$8&"|receita_pc",'Referência'!$A$2:$A$554,0)),"n.d.") -> 5347.5222 | ... M12: =IFERROR(INDEX('Referência'!$G$2:$G$554,MATCH($B$4&"|"&M$8&"|receita_pc",'Referência'!$A$2:$A$554,0)),"n.d.") -> 6044.0109
B13: 3º quartil da faixa | C13: =IFERROR(INDEX('Referência'!$I$2:$I$554,MATCH($B$4&"|"&C$8&"|receita_pc",'Referência'!$A$2:$A$554,0)),"n.d.") -> 5046.4745 | D13: =IFERROR(INDEX('Referência'!$I$2:$I$554,MATCH($B$4&"|"&D$8&"|receita_pc",'Referência'!$A$2:$A$554,0)),"n.d.") -> 4966.3621 | E13: =IFERROR(INDEX('Referência'!$I$2:$I$554,MATCH($B$4&"|"&E$8&"|receita_pc",'Referência'!$A$2:$A$554,0)),"n.d.") -> 4769.173 | F13: =IFERROR(INDEX('Referência'!$I$2:$I$554,MATCH($B$4&"|"&F$8&"|receita_pc",'Referência'!$A$2:$A$554,0)),"n.d.") -> 4923.4427 | G13: =IFERROR(INDEX('Referência'!$I$2:$I$554,MATCH($B$4&"|"&G$8&"|receita_pc",'Referência'!$A$2:$A$554,0)),"n.d.") -> 5061.9004 | H13: =IFERROR(INDEX('Referência'!$I$2:$I$554,MATCH($B$4&"|"&H$8&"|receita_pc",'Referência'!$A$2:$A$554,0)),"n.d.") -> 5307.5948 | I13: =IFERROR(INDEX('Referência'!$I$2:$I$554,MATCH($B$4&"|"&I$8&"|receita_pc",'Referência'!$A$2:$A$554,0)),"n.d.") -> 5518.02 | J13: =IFERROR(INDEX('Referência'!$I$2:$I$554,MATCH($B$4&"|"&J$8&"|receita_pc",'Referência'!$A$2:$A$554,0)),"n.d.") -> 6665.3613 | ... M13: =IFERROR(INDEX('Referência'!$I$2:$I$554,MATCH($B$4&"|"&M$8&"|receita_pc",'Referência'!$A$2:$A$554,0)),"n.d.") -> 7498.9354
B14: Diferença do município para a mediana | C14: =IF(AND(ISNUMBER(C10),ISNUMBER(C11)),C10/C11-1,"n.d.") -> 0.16552731 | D14: =IF(AND(ISNUMBER(D10),ISNUMBER(D11)),D10/D11-1,"n.d.") -> 0.14177049 | E14: =IF(AND(ISNUMBER(E10),ISNUMBER(E11)),E10/E11-1,"n.d.") -> 0.050624899 | F14: =IF(AND(ISNUMBER(F10),ISNUMBER(F11)),F10/F11-1,"n.d.") -> 0.002838999 | G14: =IF(AND(ISNUMBER(G10),ISNUMBER(G11)),G10/G11-1,"n.d.") -> -0.0001308539 | H14: =IF(AND(ISNUMBER(H10),ISNUMBER(H11)),H10/H11-1,"n.d.") -> 0.012205877 | I14: =IF(AND(ISNUMBER(I10),ISNUMBER(I11)),I10/I11-1,"n.d.") -> -0.027621584 | J14: =IF(AND(ISNUMBER(J10),ISNUMBER(J11)),J10/J11-1,"n.d.") -> -0.047908159 | ... M14: =IF(AND(ISNUMBER(M10),ISNUMBER(M11)),M10/M11-1,"n.d.") -> -0.048675394
A16: Dependência de transferências | B16: Valor do município | C16: =IFERROR(INDEX('Dados'!$G$2:$G$7096,MATCH($B$3&"|"&C$8,'Dados'!$A$2:$A$7096,0)),"n.d.") -> 79.928505 | D16: =IFERROR(INDEX('Dados'!$G$2:$G$7096,MATCH($B$3&"|"&D$8,'Dados'!$A$2:$A$7096,0)),"n.d.") -> 81.987635 | E16: =IFERROR(INDEX('Dados'!$G$2:$G$7096,MATCH($B$3&"|"&E$8,'Dados'!$A$2:$A$7096,0)),"n.d.") -> 79.996101 | F16: =IFERROR(INDEX('Dados'!$G$2:$G$7096,MATCH($B$3&"|"&F$8,'Dados'!$A$2:$A$7096,0)),"n.d.") -> 79.703073 | G16: =IFERROR(INDEX('Dados'!$G$2:$G$7096,MATCH($B$3&"|"&G$8,'Dados'!$A$2:$A$7096,0)),"n.d.") -> 82.049398 | H16: =IFERROR(INDEX('Dados'!$G$2:$G$7096,MATCH($B$3&"|"&H$8,'Dados'!$A$2:$A$7096,0)),"n.d.") -> 83.909266 | I16: =IFERROR(INDEX('Dados'!$G$2:$G$7096,MATCH($B$3&"|"&I$8,'Dados'!$A$2:$A$7096,0)),"n.d.") -> 83.521184 | J16: =IFERROR(INDEX('Dados'!$G$2:$G$7096,MATCH($B$3&"|"&J$8,'Dados'!$A$2:$A$7096,0)),"n.d.") -> 81.939577 | ... M16: =IFERROR(INDEX('Dados'!$G$2:$G$7096,MATCH($B$3&"|"&M$8,'Dados'!$A$2:$A$7096,0)),"n.d.") -> 81.244751
B17: Mediana da faixa | C17: =IFERROR(INDEX('Referência'!$H$2:$H$554,MATCH($B$4&"|"&C$8&"|dependencia_transf",'Referência'!$A$2:$A$554,0)),"n.d.") -> 84.913758 | D17: =IFERROR(INDEX('Referência'!$H$2:$H$554,MATCH($B$4&"|"&D$8&"|dependencia_transf",'Referência'!$A$2:$A$554,0)),"n.d.") -> 84.853356 | E17: =IFERROR(INDEX('Referência'!$H$2:$H$554,MATCH($B$4&"|"&E$8&"|dependencia_transf",'Referência'!$A$2:$A$554,0)),"n.d.") -> 84.084433 | F17: =IFERROR(INDEX('Referência'!$H$2:$H$554,MATCH($B$4&"|"&F$8&"|dependencia_transf",'Referência'!$A$2:$A$554,0)),"n.d.") -> 84.003347 | G17: =IFERROR(INDEX('Referência'!$H$2:$H$554,MATCH($B$4&"|"&G$8&"|dependencia_transf",'Referência'!$A$2:$A$554,0)),"n.d.") -> 83.739095 | H17: =IFERROR(INDEX('Referência'!$H$2:$H$554,MATCH($B$4&"|"&H$8&"|dependencia_transf",'Referência'!$A$2:$A$554,0)),"n.d.") -> 84.357034 | I17: =IFERROR(INDEX('Referência'!$H$2:$H$554,MATCH($B$4&"|"&I$8&"|dependencia_transf",'Referência'!$A$2:$A$554,0)),"n.d.") -> 83.823769 | J17: =IFERROR(INDEX('Referência'!$H$2:$H$554,MATCH($B$4&"|"&J$8&"|dependencia_transf",'Referência'!$A$2:$A$554,0)),"n.d.") -> 82.536062 | ... M17: =IFERROR(INDEX('Referência'!$H$2:$H$554,MATCH($B$4&"|"&M$8&"|dependencia_transf",'Referência'!$A$2:$A$554,0)),"n.d.") -> 82.033032
B18: 1º quartil da faixa | C18: =IFERROR(INDEX('Referência'!$G$2:$G$554,MATCH($B$4&"|"&C$8&"|dependencia_transf",'Referência'!$A$2:$A$554,0)),"n.d.") -> 79.360838 | D18: =IFERROR(INDEX('Referência'!$G$2:$G$554,MATCH($B$4&"|"&D$8&"|dependencia_transf",'Referência'!$A$2:$A$554,0)),"n.d.") -> 78.747321 | E18: =IFERROR(INDEX('Referência'!$G$2:$G$554,MATCH($B$4&"|"&E$8&"|dependencia_transf",'Referência'!$A$2:$A$554,0)),"n.d.") -> 77.730738 | F18: =IFERROR(INDEX('Referência'!$G$2:$G$554,MATCH($B$4&"|"&F$8&"|dependencia_transf",'Referência'!$A$2:$A$554,0)),"n.d.") -> 78.385379 | G18: =IFERROR(INDEX('Referência'!$G$2:$G$554,MATCH($B$4&"|"&G$8&"|dependencia_transf",'Referência'!$A$2:$A$554,0)),"n.d.") -> 79.089062 | H18: =IFERROR(INDEX('Referência'!$G$2:$G$554,MATCH($B$4&"|"&H$8&"|dependencia_transf",'Referência'!$A$2:$A$554,0)),"n.d.") -> 79.968899 | I18: =IFERROR(INDEX('Referência'!$G$2:$G$554,MATCH($B$4&"|"&I$8&"|dependencia_transf",'Referência'!$A$2:$A$554,0)),"n.d.") -> 80.656487 | J18: =IFERROR(INDEX('Referência'!$G$2:$G$554,MATCH($B$4&"|"&J$8&"|dependencia_transf",'Referência'!$A$2:$A$554,0)),"n.d.") -> 78.622791 | ... M18: =IFERROR(INDEX('Referência'!$G$2:$G$554,MATCH($B$4&"|"&M$8&"|dependencia_transf",'Referência'!$A$2:$A$554,0)),"n.d.") -> 78.914381
B19: 3º quartil da faixa | C19: =IFERROR(INDEX('Referência'!$I$2:$I$554,MATCH($B$4&"|"&C$8&"|dependencia_transf",'Referência'!$A$2:$A$554,0)),"n.d.") -> 87.33432 | D19: =IFERROR(INDEX('Referência'!$I$2:$I$554,MATCH($B$4&"|"&D$8&"|dependencia_transf",'Referência'!$A$2:$A$554,0)),"n.d.") -> 89.401164 | E19: =IFERROR(INDEX('Referência'!$I$2:$I$554,MATCH($B$4&"|"&E$8&"|dependencia_transf",'Referência'!$A$2:$A$554,0)),"n.d.") -> 86.894214 | F19: =IFERROR(INDEX('Referência'!$I$2:$I$554,MATCH($B$4&"|"&F$8&"|dependencia_transf",'Referência'!$A$2:$A$554,0)),"n.d.") -> 87.921012 | G19: =IFERROR(INDEX('Referência'!$I$2:$I$554,MATCH($B$4&"|"&G$8&"|dependencia_transf",'Referência'!$A$2:$A$554,0)),"n.d.") -> 86.664912 | H19: =IFERROR(INDEX('Referência'!$I$2:$I$554,MATCH($B$4&"|"&H$8&"|dependencia_transf",'Referência'!$A$2:$A$554,0)),"n.d.") -> 87.141898 | I19: =IFERROR(INDEX('Referência'!$I$2:$I$554,MATCH($B$4&"|"&I$8&"|dependencia_transf",'Referência'!$A$2:$A$554,0)),"n.d.") -> 87.668969 | J19: =IFERROR(INDEX('Referência'!$I$2:$I$554,MATCH($B$4&"|"&J$8&"|dependencia_transf",'Referência'!$A$2:$A$554,0)),"n.d.") -> 86.027153 | ... M19: =IFERROR(INDEX('Referência'!$I$2:$I$554,MATCH($B$4&"|"&M$8&"|dependencia_transf",'Referência'!$A$2:$A$554,0)),"n.d.") -> 85.825342
B20: Diferença do município para a mediana | C20: =IF(AND(ISNUMBER(C16),ISNUMBER(C17)),C16/C17-1,"n.d.") -> -0.058709598 | D20: =IF(AND(ISNUMBER(D16),ISNUMBER(D17)),D16/D17-1,"n.d.") -> -0.033772635 | E20: =IF(AND(ISNUMBER(E16),ISNUMBER(E17)),E16/E17-1,"n.d.") -> -0.048621752 | F20: =IF(AND(ISNUMBER(F16),ISNUMBER(F17)),F16/F17-1,"n.d.") -> -0.051191706 | G20: =IF(AND(ISNUMBER(G16),ISNUMBER(G17)),G16/G17-1,"n.d.") -> -0.020178121 | H20: =IF(AND(ISNUMBER(H16),ISNUMBER(H17)),H16/H17-1,"n.d.") -> -0.0053080115 | I20: =IF(AND(ISNUMBER(I16),ISNUMBER(I17)),I16/I17-1,"n.d.") -> -0.0036097783 | J20: =IF(AND(ISNUMBER(J16),ISNUMBER(J17)),J16/J17-1,"n.d.") -> -0.0072269669 | ... M20: =IF(AND(ISNUMBER(M16),ISNUMBER(M17)),M16/M17-1,"n.d.") -> -0.0096093164
A22: Despesa com saúde por habitante | B22: Valor do município | C22: =IFERROR(INDEX('Dados'!$H$2:$H$7096,MATCH($B$3&"|"&C$8,'Dados'!$A$2:$A$7096,0)),"n.d.") -> 1057.2097 | D22: =IFERROR(INDEX('Dados'!$H$2:$H$7096,MATCH($B$3&"|"&D$8,'Dados'!$A$2:$A$7096,0)),"n.d.") -> 1138.1876 | E22: =IFERROR(INDEX('Dados'!$H$2:$H$7096,MATCH($B$3&"|"&E$8,'Dados'!$A$2:$A$7096,0)),"n.d.") -> 1063.1911 | F22: =IFERROR(INDEX('Dados'!$H$2:$H$7096,MATCH($B$3&"|"&F$8,'Dados'!$A$2:$A$7096,0)),"n.d.") -> 1196.3399 | G22: =IFERROR(INDEX('Dados'!$H$2:$H$7096,MATCH($B$3&"|"&G$8,'Dados'!$A$2:$A$7096,0)),"n.d.") -> 1169.1047 | H22: =IFERROR(INDEX('Dados'!$H$2:$H$7096,MATCH($B$3&"|"&H$8,'Dados'!$A$2:$A$7096,0)),"n.d.") -> 1390.2012 | I22: =IFERROR(INDEX('Dados'!$H$2:$H$7096,MATCH($B$3&"|"&I$8,'Dados'!$A$2:$A$7096,0)),"n.d.") -> 1410.7054 | J22: =IFERROR(INDEX('Dados'!$H$2:$H$7096,MATCH($B$3&"|"&J$8,'Dados'!$A$2:$A$7096,0)),"n.d.") -> 1502.2682 | ... M22: =IFERROR(INDEX('Dados'!$H$2:$H$7096,MATCH($B$3&"|"&M$8,'Dados'!$A$2:$A$7096,0)),"n.d.") -> 2245.8282
B23: Mediana da faixa | C23: =IFERROR(INDEX('Referência'!$H$2:$H$554,MATCH($B$4&"|"&C$8&"|saude_pc",'Referência'!$A$2:$A$554,0)),"n.d.") -> 1134.7828 | D23: =IFERROR(INDEX('Referência'!$H$2:$H$554,MATCH($B$4&"|"&D$8&"|saude_pc",'Referência'!$A$2:$A$554,0)),"n.d.") -> 1102.9277 | E23: =IFERROR(INDEX('Referência'!$H$2:$H$554,MATCH($B$4&"|"&E$8&"|saude_pc",'Referência'!$A$2:$A$554,0)),"n.d.") -> 1094.0141 | F23: =IFERROR(INDEX('Referência'!$H$2:$H$554,MATCH($B$4&"|"&F$8&"|saude_pc",'Referência'!$A$2:$A$554,0)),"n.d.") -> 1164.7485 | G23: =IFERROR(INDEX('Referência'!$H$2:$H$554,MATCH($B$4&"|"&G$8&"|saude_pc",'Referência'!$A$2:$A$554,0)),"n.d.") -> 1198.6196 | H23: =IFERROR(INDEX('Referência'!$H$2:$H$554,MATCH($B$4&"|"&H$8&"|saude_pc",'Referência'!$A$2:$A$554,0)),"n.d.") -> 1376.0859 | I23: =IFERROR(INDEX('Referência'!$H$2:$H$554,MATCH($B$4&"|"&I$8&"|saude_pc",'Referência'!$A$2:$A$554,0)),"n.d.") -> 1394.7782 | J23: =IFERROR(INDEX('Referência'!$H$2:$H$554,MATCH($B$4&"|"&J$8&"|saude_pc",'Referência'!$A$2:$A$554,0)),"n.d.") -> 1585.4145 | ... M23: =IFERROR(INDEX('Referência'!$H$2:$H$554,MATCH($B$4&"|"&M$8&"|saude_pc",'Referência'!$A$2:$A$554,0)),"n.d.") -> 1892.7691
B24: 1º quartil da faixa | C24: =IFERROR(INDEX('Referência'!$G$2:$G$554,MATCH($B$4&"|"&C$8&"|saude_pc",'Referência'!$A$2:$A$554,0)),"n.d.") -> 992.23257 | D24: =IFERROR(INDEX('Referência'!$G$2:$G$554,MATCH($B$4&"|"&D$8&"|saude_pc",'Referência'!$A$2:$A$554,0)),"n.d.") -> 964.24772 | E24: =IFERROR(INDEX('Referência'!$G$2:$G$554,MATCH($B$4&"|"&E$8&"|saude_pc",'Referência'!$A$2:$A$554,0)),"n.d.") -> 937.86276 | F24: =IFERROR(INDEX('Referência'!$G$2:$G$554,MATCH($B$4&"|"&F$8&"|saude_pc",'Referência'!$A$2:$A$554,0)),"n.d.") -> 1024.3356 | G24: =IFERROR(INDEX('Referência'!$G$2:$G$554,MATCH($B$4&"|"&G$8&"|saude_pc",'Referência'!$A$2:$A$554,0)),"n.d.") -> 1026.5609 | H24: =IFERROR(INDEX('Referência'!$G$2:$G$554,MATCH($B$4&"|"&H$8&"|saude_pc",'Referência'!$A$2:$A$554,0)),"n.d.") -> 1164.7231 | I24: =IFERROR(INDEX('Referência'!$G$2:$G$554,MATCH($B$4&"|"&I$8&"|saude_pc",'Referência'!$A$2:$A$554,0)),"n.d.") -> 1133.1248 | J24: =IFERROR(INDEX('Referência'!$G$2:$G$554,MATCH($B$4&"|"&J$8&"|saude_pc",'Referência'!$A$2:$A$554,0)),"n.d.") -> 1413.5459 | ... M24: =IFERROR(INDEX('Referência'!$G$2:$G$554,MATCH($B$4&"|"&M$8&"|saude_pc",'Referência'!$A$2:$A$554,0)),"n.d.") -> 1625.7944
B25: 3º quartil da faixa | C25: =IFERROR(INDEX('Referência'!$I$2:$I$554,MATCH($B$4&"|"&C$8&"|saude_pc",'Referência'!$A$2:$A$554,0)),"n.d.") -> 1307.5431 | D25: =IFERROR(INDEX('Referência'!$I$2:$I$554,MATCH($B$4&"|"&D$8&"|saude_pc",'Referência'!$A$2:$A$554,0)),"n.d.") -> 1268.6569 | E25: =IFERROR(INDEX('Referência'!$I$2:$I$554,MATCH($B$4&"|"&E$8&"|saude_pc",'Referência'!$A$2:$A$554,0)),"n.d.") -> 1286.3042 | F25: =IFERROR(INDEX('Referência'!$I$2:$I$554,MATCH($B$4&"|"&F$8&"|saude_pc",'Referência'!$A$2:$A$554,0)),"n.d.") -> 1357.7814 | G25: =IFERROR(INDEX('Referência'!$I$2:$I$554,MATCH($B$4&"|"&G$8&"|saude_pc",'Referência'!$A$2:$A$554,0)),"n.d.") -> 1397.4541 | H25: =IFERROR(INDEX('Referência'!$I$2:$I$554,MATCH($B$4&"|"&H$8&"|saude_pc",'Referência'!$A$2:$A$554,0)),"n.d.") -> 1564.8586 | I25: =IFERROR(INDEX('Referência'!$I$2:$I$554,MATCH($B$4&"|"&I$8&"|saude_pc",'Referência'!$A$2:$A$554,0)),"n.d.") -> 1558.8712 | J25: =IFERROR(INDEX('Referência'!$I$2:$I$554,MATCH($B$4&"|"&J$8&"|saude_pc",'Referência'!$A$2:$A$554,0)),"n.d.") -> 1800.2935 | ... M25: =IFERROR(INDEX('Referência'!$I$2:$I$554,MATCH($B$4&"|"&M$8&"|saude_pc",'Referência'!$A$2:$A$554,0)),"n.d.") -> 2175.6439
B26: Diferença do município para a mediana | C26: =IF(AND(ISNUMBER(C22),ISNUMBER(C23)),C22/C23-1,"n.d.") -> -0.068359498 | D26: =IF(AND(ISNUMBER(D22),ISNUMBER(D23)),D22/D23-1,"n.d.") -> 0.031969365 | E26: =IF(AND(ISNUMBER(E22),ISNUMBER(E23)),E22/E23-1,"n.d.") -> -0.028174288 | F26: =IF(AND(ISNUMBER(F22),ISNUMBER(F23)),F22/F23-1,"n.d.") -> 0.027122918 | G26: =IF(AND(ISNUMBER(G22),ISNUMBER(G23)),G22/G23-1,"n.d.") -> -0.024624052 | H26: =IF(AND(ISNUMBER(H22),ISNUMBER(H23)),H22/H23-1,"n.d.") -> 0.010257548 | I26: =IF(AND(ISNUMBER(I22),ISNUMBER(I23)),I22/I23-1,"n.d.") -> 0.011419115 | J26: =IF(AND(ISNUMBER(J22),ISNUMBER(J23)),J22/J23-1,"n.d.") -> -0.052444483 | ... M26: =IF(AND(ISNUMBER(M22),ISNUMBER(M23)),M22/M23-1,"n.d.") -> 0.18653051
A28: Despesa com educação por habitante | B28: Valor do município | C28: =IFERROR(INDEX('Dados'!$I$2:$I$7096,MATCH($B$3&"|"&C$8,'Dados'!$A$2:$A$7096,0)),"n.d.") -> 1675.556 | D28: =IFERROR(INDEX('Dados'!$I$2:$I$7096,MATCH($B$3&"|"&D$8,'Dados'!$A$2:$A$7096,0)),"n.d.") -> 1580.2175 | E28: =IFERROR(INDEX('Dados'!$I$2:$I$7096,MATCH($B$3&"|"&E$8,'Dados'!$A$2:$A$7096,0)),"n.d.") -> 1565.7475 | F28: =IFERROR(INDEX('Dados'!$I$2:$I$7096,MATCH($B$3&"|"&F$8,'Dados'!$A$2:$A$7096,0)),"n.d.") -> 1638.7483 | G28: =IFERROR(INDEX('Dados'!$I$2:$I$7096,MATCH($B$3&"|"&G$8,'Dados'!$A$2:$A$7096,0)),"n.d.") -> 1634.753 | H28: =IFERROR(INDEX('Dados'!$I$2:$I$7096,MATCH($B$3&"|"&H$8,'Dados'!$A$2:$A$7096,0)),"n.d.") -> 1522.3292 | I28: =IFERROR(INDEX('Dados'!$I$2:$I$7096,MATCH($B$3&"|"&I$8,'Dados'!$A$2:$A$7096,0)),"n.d.") -> 1726.5476 | J28: =IFERROR(INDEX('Dados'!$I$2:$I$7096,MATCH($B$3&"|"&J$8,'Dados'!$A$2:$A$7096,0)),"n.d.") -> 1815.3785 | ... M28: =IFERROR(INDEX('Dados'!$I$2:$I$7096,MATCH($B$3&"|"&M$8,'Dados'!$A$2:$A$7096,0)),"n.d.") -> 1914.6131
B29: Mediana da faixa | C29: =IFERROR(INDEX('Referência'!$H$2:$H$554,MATCH($B$4&"|"&C$8&"|educacao_pc",'Referência'!$A$2:$A$554,0)),"n.d.") -> 1433.2332 | D29: =IFERROR(INDEX('Referência'!$H$2:$H$554,MATCH($B$4&"|"&D$8&"|educacao_pc",'Referência'!$A$2:$A$554,0)),"n.d.") -> 1430.9668 | E29: =IFERROR(INDEX('Referência'!$H$2:$H$554,MATCH($B$4&"|"&E$8&"|educacao_pc",'Referência'!$A$2:$A$554,0)),"n.d.") -> 1378.745 | F29: =IFERROR(INDEX('Referência'!$H$2:$H$554,MATCH($B$4&"|"&F$8&"|educacao_pc",'Referência'!$A$2:$A$554,0)),"n.d.") -> 1412.1307 | G29: =IFERROR(INDEX('Referência'!$H$2:$H$554,MATCH($B$4&"|"&G$8&"|educacao_pc",'Referência'!$A$2:$A$554,0)),"n.d.") -> 1482.8127 | H29: =IFERROR(INDEX('Referência'!$H$2:$H$554,MATCH($B$4&"|"&H$8&"|educacao_pc",'Referência'!$A$2:$A$554,0)),"n.d.") -> 1286.1207 | I29: =IFERROR(INDEX('Referência'!$H$2:$H$554,MATCH($B$4&"|"&I$8&"|educacao_pc",'Referência'!$A$2:$A$554,0)),"n.d.") -> 1391.767 | J29: =IFERROR(INDEX('Referência'!$H$2:$H$554,MATCH($B$4&"|"&J$8&"|educacao_pc",'Referência'!$A$2:$A$554,0)),"n.d.") -> 1833.279 | ... M29: =IFERROR(INDEX('Referência'!$H$2:$H$554,MATCH($B$4&"|"&M$8&"|educacao_pc",'Referência'!$A$2:$A$554,0)),"n.d.") -> 2060.5831
B30: 1º quartil da faixa | C30: =IFERROR(INDEX('Referência'!$G$2:$G$554,MATCH($B$4&"|"&C$8&"|educacao_pc",'Referência'!$A$2:$A$554,0)),"n.d.") -> 1264.6777 | D30: =IFERROR(INDEX('Referência'!$G$2:$G$554,MATCH($B$4&"|"&D$8&"|educacao_pc",'Referência'!$A$2:$A$554,0)),"n.d.") -> 1206.0409 | E30: =IFERROR(INDEX('Referência'!$G$2:$G$554,MATCH($B$4&"|"&E$8&"|educacao_pc",'Referência'!$A$2:$A$554,0)),"n.d.") -> 1168.6544 | F30: =IFERROR(INDEX('Referência'!$G$2:$G$554,MATCH($B$4&"|"&F$8&"|educacao_pc",'Referência'!$A$2:$A$554,0)),"n.d.") -> 1261.3077 | G30: =IFERROR(INDEX('Referência'!$G$2:$G$554,MATCH($B$4&"|"&G$8&"|educacao_pc",'Referência'!$A$2:$A$554,0)),"n.d.") -> 1256.3262 | H30: =IFERROR(INDEX('Referência'!$G$2:$G$554,MATCH($B$4&"|"&H$8&"|educacao_pc",'Referência'!$A$2:$A$554,0)),"n.d.") -> 1081.6543 | I30: =IFERROR(INDEX('Referência'!$G$2:$G$554,MATCH($B$4&"|"&I$8&"|educacao_pc",'Referência'!$A$2:$A$554,0)),"n.d.") -> 1202.1968 | J30: =IFERROR(INDEX('Referência'!$G$2:$G$554,MATCH($B$4&"|"&J$8&"|educacao_pc",'Referência'!$A$2:$A$554,0)),"n.d.") -> 1597.3244 | ... M30: =IFERROR(INDEX('Referência'!$G$2:$G$554,MATCH($B$4&"|"&M$8&"|educacao_pc",'Referência'!$A$2:$A$554,0)),"n.d.") -> 1745.3489
B31: 3º quartil da faixa | C31: =IFERROR(INDEX('Referência'!$I$2:$I$554,MATCH($B$4&"|"&C$8&"|educacao_pc",'Referência'!$A$2:$A$554,0)),"n.d.") -> 1749.83 | D31: =IFERROR(INDEX('Referência'!$I$2:$I$554,MATCH($B$4&"|"&D$8&"|educacao_pc",'Referência'!$A$2:$A$554,0)),"n.d.") -> 1663.8167 | E31: =IFERROR(INDEX('Referência'!$I$2:$I$554,MATCH($B$4&"|"&E$8&"|educacao_pc",'Referência'!$A$2:$A$554,0)),"n.d.") -> 1628.7719 | F31: =IFERROR(INDEX('Referência'!$I$2:$I$554,MATCH($B$4&"|"&F$8&"|educacao_pc",'Referência'!$A$2:$A$554,0)),"n.d.") -> 1647.515 | G31: =IFERROR(INDEX('Referência'!$I$2:$I$554,MATCH($B$4&"|"&G$8&"|educacao_pc",'Referência'!$A$2:$A$554,0)),"n.d.") -> 1656.732 | H31: =IFERROR(INDEX('Referência'!$I$2:$I$554,MATCH($B$4&"|"&H$8&"|educacao_pc",'Referência'!$A$2:$A$554,0)),"n.d.") -> 1483.5668 | I31: =IFERROR(INDEX('Referência'!$I$2:$I$554,MATCH($B$4&"|"&I$8&"|educacao_pc",'Referência'!$A$2:$A$554,0)),"n.d.") -> 1635.058 | J31: =IFERROR(INDEX('Referência'!$I$2:$I$554,MATCH($B$4&"|"&J$8&"|educacao_pc",'Referência'!$A$2:$A$554,0)),"n.d.") -> 2135.0595 | ... M31: =IFERROR(INDEX('Referência'!$I$2:$I$554,MATCH($B$4&"|"&M$8&"|educacao_pc",'Referência'!$A$2:$A$554,0)),"n.d.") -> 2344.0346
B32: Diferença do município para a mediana | C32: =IF(AND(ISNUMBER(C28),ISNUMBER(C29)),C28/C29-1,"n.d.") -> 0.16907418 | D32: =IF(AND(ISNUMBER(D28),ISNUMBER(D29)),D28/D29-1,"n.d.") -> 0.10430061 | E32: =IF(AND(ISNUMBER(E28),ISNUMBER(E29)),E28/E29-1,"n.d.") -> 0.13563238 | F32: =IF(AND(ISNUMBER(F28),ISNUMBER(F29)),F28/F29-1,"n.d.") -> 0.16047925 | G32: =IF(AND(ISNUMBER(G28),ISNUMBER(G29)),G28/G29-1,"n.d.") -> 0.10246756 | H32: =IF(AND(ISNUMBER(H28),ISNUMBER(H29)),H28/H29-1,"n.d.") -> 0.18365966 | I32: =IF(AND(ISNUMBER(I28),ISNUMBER(I29)),I28/I29-1,"n.d.") -> 0.24054351 | J32: =IF(AND(ISNUMBER(J28),ISNUMBER(J29)),J28/J29-1,"n.d.") -> -0.009764196 | ... M32: =IF(AND(ISNUMBER(M28),ISNUMBER(M29)),M28/M29-1,"n.d.") -> -0.070839202
A34: PIB por habitante | B34: Valor do município | C34: =IFERROR(INDEX('Dados'!$J$2:$J$7096,MATCH($B$3&"|"&C$8,'Dados'!$A$2:$A$7096,0)),"n.d.") -> 30283.692 | D34: =IFERROR(INDEX('Dados'!$J$2:$J$7096,MATCH($B$3&"|"&D$8,'Dados'!$A$2:$A$7096,0)),"n.d.") -> 29505.838 | E34: =IFERROR(INDEX('Dados'!$J$2:$J$7096,MATCH($B$3&"|"&E$8,'Dados'!$A$2:$A$7096,0)),"n.d.") -> 31068.419 | F34: =IFERROR(INDEX('Dados'!$J$2:$J$7096,MATCH($B$3&"|"&F$8,'Dados'!$A$2:$A$7096,0)),"n.d.") -> 29739.55 | G34: =IFERROR(INDEX('Dados'!$J$2:$J$7096,MATCH($B$3&"|"&G$8,'Dados'!$A$2:$A$7096,0)),"n.d.") -> 27716.105 | H34: =IFERROR(INDEX('Dados'!$J$2:$J$7096,MATCH($B$3&"|"&H$8,'Dados'!$A$2:$A$7096,0)),"n.d.") -> 29068.691 | I34: =IFERROR(INDEX('Dados'!$J$2:$J$7096,MATCH($B$3&"|"&I$8,'Dados'!$A$2:$A$7096,0)),"n.d.") -> 31532.342 | J34: =IFERROR(INDEX('Dados'!$J$2:$J$7096,MATCH($B$3&"|"&J$8,'Dados'!$A$2:$A$7096,0)),"n.d.") -> 33576.387 | ... M34: =IFERROR(INDEX('Dados'!$J$2:$J$7096,MATCH($B$3&"|"&M$8,'Dados'!$A$2:$A$7096,0)),"n.d.") -> n.d.
B35: Mediana da faixa | C35: =IFERROR(INDEX('Referência'!$H$2:$H$554,MATCH($B$4&"|"&C$8&"|pib_pc",'Referência'!$A$2:$A$554,0)),"n.d.") -> 33277.793 | D35: =IFERROR(INDEX('Referência'!$H$2:$H$554,MATCH($B$4&"|"&D$8&"|pib_pc",'Referência'!$A$2:$A$554,0)),"n.d.") -> 33258.864 | E35: =IFERROR(INDEX('Referência'!$H$2:$H$554,MATCH($B$4&"|"&E$8&"|pib_pc",'Referência'!$A$2:$A$554,0)),"n.d.") -> 33251.675 | F35: =IFERROR(INDEX('Referência'!$H$2:$H$554,MATCH($B$4&"|"&F$8&"|pib_pc",'Referência'!$A$2:$A$554,0)),"n.d.") -> 30201.995 | G35: =IFERROR(INDEX('Referência'!$H$2:$H$554,MATCH($B$4&"|"&G$8&"|pib_pc",'Referência'!$A$2:$A$554,0)),"n.d.") -> 32612.189 | H35: =IFERROR(INDEX('Referência'!$H$2:$H$554,MATCH($B$4&"|"&H$8&"|pib_pc",'Referência'!$A$2:$A$554,0)),"n.d.") -> 35960.585 | I35: =IFERROR(INDEX('Referência'!$H$2:$H$554,MATCH($B$4&"|"&I$8&"|pib_pc",'Referência'!$A$2:$A$554,0)),"n.d.") -> 36497.025 | J35: =IFERROR(INDEX('Referência'!$H$2:$H$554,MATCH($B$4&"|"&J$8&"|pib_pc",'Referência'!$A$2:$A$554,0)),"n.d.") -> 37630.58 | ... M35: =IFERROR(INDEX('Referência'!$H$2:$H$554,MATCH($B$4&"|"&M$8&"|pib_pc",'Referência'!$A$2:$A$554,0)),"n.d.") -> n.d.
B36: 1º quartil da faixa | C36: =IFERROR(INDEX('Referência'!$G$2:$G$554,MATCH($B$4&"|"&C$8&"|pib_pc",'Referência'!$A$2:$A$554,0)),"n.d.") -> 25386.09 | D36: =IFERROR(INDEX('Referência'!$G$2:$G$554,MATCH($B$4&"|"&D$8&"|pib_pc",'Referência'!$A$2:$A$554,0)),"n.d.") -> 25668.627 | E36: =IFERROR(INDEX('Referência'!$G$2:$G$554,MATCH($B$4&"|"&E$8&"|pib_pc",'Referência'!$A$2:$A$554,0)),"n.d.") -> 27109.391 | F36: =IFERROR(INDEX('Referência'!$G$2:$G$554,MATCH($B$4&"|"&F$8&"|pib_pc",'Referência'!$A$2:$A$554,0)),"n.d.") -> 26039.806 | G36: =IFERROR(INDEX('Referência'!$G$2:$G$554,MATCH($B$4&"|"&G$8&"|pib_pc",'Referência'!$A$2:$A$554,0)),"n.d.") -> 26082.265 | H36: =IFERROR(INDEX('Referência'!$G$2:$G$554,MATCH($B$4&"|"&H$8&"|pib_pc",'Referência'!$A$2:$A$554,0)),"n.d.") -> 26607.673 | I36: =IFERROR(INDEX('Referência'!$G$2:$G$554,MATCH($B$4&"|"&I$8&"|pib_pc",'Referência'!$A$2:$A$554,0)),"n.d.") -> 26372.371 | J36: =IFERROR(INDEX('Referência'!$G$2:$G$554,MATCH($B$4&"|"&J$8&"|pib_pc",'Referência'!$A$2:$A$554,0)),"n.d.") -> 27165.744 | ... M36: =IFERROR(INDEX('Referência'!$G$2:$G$554,MATCH($B$4&"|"&M$8&"|pib_pc",'Referência'!$A$2:$A$554,0)),"n.d.") -> n.d.
B37: 3º quartil da faixa | C37: =IFERROR(INDEX('Referência'!$I$2:$I$554,MATCH($B$4&"|"&C$8&"|pib_pc",'Referência'!$A$2:$A$554,0)),"n.d.") -> 47098.282 | D37: =IFERROR(INDEX('Referência'!$I$2:$I$554,MATCH($B$4&"|"&D$8&"|pib_pc",'Referência'!$A$2:$A$554,0)),"n.d.") -> 44950.726 | E37: =IFERROR(INDEX('Referência'!$I$2:$I$554,MATCH($B$4&"|"&E$8&"|pib_pc",'Referência'!$A$2:$A$554,0)),"n.d.") -> 47424.575 | F37: =IFERROR(INDEX('Referência'!$I$2:$I$554,MATCH($B$4&"|"&F$8&"|pib_pc",'Referência'!$A$2:$A$554,0)),"n.d.") -> 42164.019 | G37: =IFERROR(INDEX('Referência'!$I$2:$I$554,MATCH($B$4&"|"&G$8&"|pib_pc",'Referência'!$A$2:$A$554,0)),"n.d.") -> 42832.169 | H37: =IFERROR(INDEX('Referência'!$I$2:$I$554,MATCH($B$4&"|"&H$8&"|pib_pc",'Referência'!$A$2:$A$554,0)),"n.d.") -> 47007.37 | I37: =IFERROR(INDEX('Referência'!$I$2:$I$554,MATCH($B$4&"|"&I$8&"|pib_pc",'Referência'!$A$2:$A$554,0)),"n.d.") -> 48142.299 | J37: =IFERROR(INDEX('Referência'!$I$2:$I$554,MATCH($B$4&"|"&J$8&"|pib_pc",'Referência'!$A$2:$A$554,0)),"n.d.") -> 49051.929 | ... M37: =IFERROR(INDEX('Referência'!$I$2:$I$554,MATCH($B$4&"|"&M$8&"|pib_pc",'Referência'!$A$2:$A$554,0)),"n.d.") -> n.d.
B38: Diferença do município para a mediana | C38: =IF(AND(ISNUMBER(C34),ISNUMBER(C35)),C34/C35-1,"n.d.") -> -0.08997295 | D38: =IF(AND(ISNUMBER(D34),ISNUMBER(D35)),D34/D35-1,"n.d.") -> -0.11284287 | E38: =IF(AND(ISNUMBER(E34),ISNUMBER(E35)),E34/E35-1,"n.d.") -> -0.065658529 | F38: =IF(AND(ISNUMBER(F34),ISNUMBER(F35)),F34/F35-1,"n.d.") -> -0.015311758 | G38: =IF(AND(ISNUMBER(G34),ISNUMBER(G35)),G34/G35-1,"n.d.") -> -0.1501305 | H38: =IF(AND(ISNUMBER(H34),ISNUMBER(H35)),H34/H35-1,"n.d.") -> -0.19165132 | I38: =IF(AND(ISNUMBER(I34),ISNUMBER(I35)),I34/I35-1,"n.d.") -> -0.1360298 | J38: =IF(AND(ISNUMBER(J34),ISNUMBER(J35)),J34/J35-1,"n.d.") -> -0.10773665 | ... M38: =IF(AND(ISNUMBER(M34),ISNUMBER(M35)),M34/M35-1,"n.d.") -> n.d.
A40: Ideb dos anos iniciais, rede municipal | B40: Valor do município | C40: =IFERROR(INDEX('Dados'!$K$2:$K$7096,MATCH($B$3&"|"&C$8,'Dados'!$A$2:$A$7096,0)),"n.d.") -> 7.5 | D40: =IFERROR(INDEX('Dados'!$K$2:$K$7096,MATCH($B$3&"|"&D$8,'Dados'!$A$2:$A$7096,0)),"n.d.") -> n.d. | E40: =IFERROR(INDEX('Dados'!$K$2:$K$7096,MATCH($B$3&"|"&E$8,'Dados'!$A$2:$A$7096,0)),"n.d.") -> 7.5 | F40: =IFERROR(INDEX('Dados'!$K$2:$K$7096,MATCH($B$3&"|"&F$8,'Dados'!$A$2:$A$7096,0)),"n.d.") -> n.d. | G40: =IFERROR(INDEX('Dados'!$K$2:$K$7096,MATCH($B$3&"|"&G$8,'Dados'!$A$2:$A$7096,0)),"n.d.") -> 7.3 | H40: =IFERROR(INDEX('Dados'!$K$2:$K$7096,MATCH($B$3&"|"&H$8,'Dados'!$A$2:$A$7096,0)),"n.d.") -> n.d. | I40: =IFERROR(INDEX('Dados'!$K$2:$K$7096,MATCH($B$3&"|"&I$8,'Dados'!$A$2:$A$7096,0)),"n.d.") -> 6 | J40: =IFERROR(INDEX('Dados'!$K$2:$K$7096,MATCH($B$3&"|"&J$8,'Dados'!$A$2:$A$7096,0)),"n.d.") -> n.d. | ... M40: =IFERROR(INDEX('Dados'!$K$2:$K$7096,MATCH($B$3&"|"&M$8,'Dados'!$A$2:$A$7096,0)),"n.d.") -> n.d.
B41: Mediana da faixa | C41: =IFERROR(INDEX('Referência'!$H$2:$H$554,MATCH($B$4&"|"&C$8&"|ideb",'Referência'!$A$2:$A$554,0)),"n.d.") -> 6.1 | D41: =IFERROR(INDEX('Referência'!$H$2:$H$554,MATCH($B$4&"|"&D$8&"|ideb",'Referência'!$A$2:$A$554,0)),"n.d.") -> n.d. | E41: =IFERROR(INDEX('Referência'!$H$2:$H$554,MATCH($B$4&"|"&E$8&"|ideb",'Referência'!$A$2:$A$554,0)),"n.d.") -> 6.5 | F41: =IFERROR(INDEX('Referência'!$H$2:$H$554,MATCH($B$4&"|"&F$8&"|ideb",'Referência'!$A$2:$A$554,0)),"n.d.") -> n.d. | G41: =IFERROR(INDEX('Referência'!$H$2:$H$554,MATCH($B$4&"|"&G$8&"|ideb",'Referência'!$A$2:$A$554,0)),"n.d.") -> 6.5 | H41: =IFERROR(INDEX('Referência'!$H$2:$H$554,MATCH($B$4&"|"&H$8&"|ideb",'Referência'!$A$2:$A$554,0)),"n.d.") -> n.d. | I41: =IFERROR(INDEX('Referência'!$H$2:$H$554,MATCH($B$4&"|"&I$8&"|ideb",'Referência'!$A$2:$A$554,0)),"n.d.") -> 6.1 | J41: =IFERROR(INDEX('Referência'!$H$2:$H$554,MATCH($B$4&"|"&J$8&"|ideb",'Referência'!$A$2:$A$554,0)),"n.d.") -> n.d. | ... M41: =IFERROR(INDEX('Referência'!$H$2:$H$554,MATCH($B$4&"|"&M$8&"|ideb",'Referência'!$A$2:$A$554,0)),"n.d.") -> n.d.
B42: 1º quartil da faixa | C42: =IFERROR(INDEX('Referência'!$G$2:$G$554,MATCH($B$4&"|"&C$8&"|ideb",'Referência'!$A$2:$A$554,0)),"n.d.") -> 5.9 | D42: =IFERROR(INDEX('Referência'!$G$2:$G$554,MATCH($B$4&"|"&D$8&"|ideb",'Referência'!$A$2:$A$554,0)),"n.d.") -> n.d. | E42: =IFERROR(INDEX('Referência'!$G$2:$G$554,MATCH($B$4&"|"&E$8&"|ideb",'Referência'!$A$2:$A$554,0)),"n.d.") -> 6.2 | F42: =IFERROR(INDEX('Referência'!$G$2:$G$554,MATCH($B$4&"|"&F$8&"|ideb",'Referência'!$A$2:$A$554,0)),"n.d.") -> n.d. | G42: =IFERROR(INDEX('Referência'!$G$2:$G$554,MATCH($B$4&"|"&G$8&"|ideb",'Referência'!$A$2:$A$554,0)),"n.d.") -> 6.3 | H42: =IFERROR(INDEX('Referência'!$G$2:$G$554,MATCH($B$4&"|"&H$8&"|ideb",'Referência'!$A$2:$A$554,0)),"n.d.") -> n.d. | I42: =IFERROR(INDEX('Referência'!$G$2:$G$554,MATCH($B$4&"|"&I$8&"|ideb",'Referência'!$A$2:$A$554,0)),"n.d.") -> 5.8 | J42: =IFERROR(INDEX('Referência'!$G$2:$G$554,MATCH($B$4&"|"&J$8&"|ideb",'Referência'!$A$2:$A$554,0)),"n.d.") -> n.d. | ... M42: =IFERROR(INDEX('Referência'!$G$2:$G$554,MATCH($B$4&"|"&M$8&"|ideb",'Referência'!$A$2:$A$554,0)),"n.d.") -> n.d.
B43: 3º quartil da faixa | C43: =IFERROR(INDEX('Referência'!$I$2:$I$554,MATCH($B$4&"|"&C$8&"|ideb",'Referência'!$A$2:$A$554,0)),"n.d.") -> 6.4 | D43: =IFERROR(INDEX('Referência'!$I$2:$I$554,MATCH($B$4&"|"&D$8&"|ideb",'Referência'!$A$2:$A$554,0)),"n.d.") -> n.d. | E43: =IFERROR(INDEX('Referência'!$I$2:$I$554,MATCH($B$4&"|"&E$8&"|ideb",'Referência'!$A$2:$A$554,0)),"n.d.") -> 6.7 | F43: =IFERROR(INDEX('Referência'!$I$2:$I$554,MATCH($B$4&"|"&F$8&"|ideb",'Referência'!$A$2:$A$554,0)),"n.d.") -> n.d. | G43: =IFERROR(INDEX('Referência'!$I$2:$I$554,MATCH($B$4&"|"&G$8&"|ideb",'Referência'!$A$2:$A$554,0)),"n.d.") -> 6.9 | H43: =IFERROR(INDEX('Referência'!$I$2:$I$554,MATCH($B$4&"|"&H$8&"|ideb",'Referência'!$A$2:$A$554,0)),"n.d.") -> n.d. | I43: =IFERROR(INDEX('Referência'!$I$2:$I$554,MATCH($B$4&"|"&I$8&"|ideb",'Referência'!$A$2:$A$554,0)),"n.d.") -> 6.3 | J43: =IFERROR(INDEX('Referência'!$I$2:$I$554,MATCH($B$4&"|"&J$8&"|ideb",'Referência'!$A$2:$A$554,0)),"n.d.") -> n.d. | ... M43: =IFERROR(INDEX('Referência'!$I$2:$I$554,MATCH($B$4&"|"&M$8&"|ideb",'Referência'!$A$2:$A$554,0)),"n.d.") -> n.d.
B44: Diferença do município para a mediana | C44: =IF(AND(ISNUMBER(C40),ISNUMBER(C41)),C40/C41-1,"n.d.") -> 0.2295082 | D44: =IF(AND(ISNUMBER(D40),ISNUMBER(D41)),D40/D41-1,"n.d.") -> n.d. | E44: =IF(AND(ISNUMBER(E40),ISNUMBER(E41)),E40/E41-1,"n.d.") -> 0.15384615 | F44: =IF(AND(ISNUMBER(F40),ISNUMBER(F41)),F40/F41-1,"n.d.") -> n.d. | G44: =IF(AND(ISNUMBER(G40),ISNUMBER(G41)),G40/G41-1,"n.d.") -> 0.12307692 | H44: =IF(AND(ISNUMBER(H40),ISNUMBER(H41)),H40/H41-1,"n.d.") -> n.d. | I44: =IF(AND(ISNUMBER(I40),ISNUMBER(I41)),I40/I41-1,"n.d.") -> -0.016393443 | J44: =IF(AND(ISNUMBER(J40),ISNUMBER(J41)),J40/J41-1,"n.d.") -> n.d. | ... M44: =IF(AND(ISNUMBER(M40),ISNUMBER(M41)),M40/M41-1,"n.d.") -> n.d.
A46: Nascidos de mães com 7 ou mais consultas de pré-natal | B46: Valor do município | C46: =IFERROR(INDEX('Dados'!$L$2:$L$7096,MATCH($B$3&"|"&C$8,'Dados'!$A$2:$A$7096,0)),"n.d.") -> 90.151515 | D46: =IFERROR(INDEX('Dados'!$L$2:$L$7096,MATCH($B$3&"|"&D$8,'Dados'!$A$2:$A$7096,0)),"n.d.") -> 89.041096 | E46: =IFERROR(INDEX('Dados'!$L$2:$L$7096,MATCH($B$3&"|"&E$8,'Dados'!$A$2:$A$7096,0)),"n.d.") -> 92.465753 | F46: =IFERROR(INDEX('Dados'!$L$2:$L$7096,MATCH($B$3&"|"&F$8,'Dados'!$A$2:$A$7096,0)),"n.d.") -> 82.8125 | G46: =IFERROR(INDEX('Dados'!$L$2:$L$7096,MATCH($B$3&"|"&G$8,'Dados'!$A$2:$A$7096,0)),"n.d.") -> 80.141844 | H46: =IFERROR(INDEX('Dados'!$L$2:$L$7096,MATCH($B$3&"|"&H$8,'Dados'!$A$2:$A$7096,0)),"n.d.") -> 77.862595 | I46: =IFERROR(INDEX('Dados'!$L$2:$L$7096,MATCH($B$3&"|"&I$8,'Dados'!$A$2:$A$7096,0)),"n.d.") -> 82.644628 | J46: =IFERROR(INDEX('Dados'!$L$2:$L$7096,MATCH($B$3&"|"&J$8,'Dados'!$A$2:$A$7096,0)),"n.d.") -> 88.461538 | ... M46: =IFERROR(INDEX('Dados'!$L$2:$L$7096,MATCH($B$3&"|"&M$8,'Dados'!$A$2:$A$7096,0)),"n.d.") -> n.d.
B47: Mediana da faixa | C47: =IFERROR(INDEX('Referência'!$H$2:$H$554,MATCH($B$4&"|"&C$8&"|pre_natal_7mais",'Referência'!$A$2:$A$554,0)),"n.d.") -> 81.857367 | D47: =IFERROR(INDEX('Referência'!$H$2:$H$554,MATCH($B$4&"|"&D$8&"|pre_natal_7mais",'Referência'!$A$2:$A$554,0)),"n.d.") -> 81.31467 | E47: =IFERROR(INDEX('Referência'!$H$2:$H$554,MATCH($B$4&"|"&E$8&"|pre_natal_7mais",'Referência'!$A$2:$A$554,0)),"n.d.") -> 81.713836 | F47: =IFERROR(INDEX('Referência'!$H$2:$H$554,MATCH($B$4&"|"&F$8&"|pre_natal_7mais",'Referência'!$A$2:$A$554,0)),"n.d.") -> 85.278638 | G47: =IFERROR(INDEX('Referência'!$H$2:$H$554,MATCH($B$4&"|"&G$8&"|pre_natal_7mais",'Referência'!$A$2:$A$554,0)),"n.d.") -> 85.251156 | H47: =IFERROR(INDEX('Referência'!$H$2:$H$554,MATCH($B$4&"|"&H$8&"|pre_natal_7mais",'Referência'!$A$2:$A$554,0)),"n.d.") -> 84.094213 | I47: =IFERROR(INDEX('Referência'!$H$2:$H$554,MATCH($B$4&"|"&I$8&"|pre_natal_7mais",'Referência'!$A$2:$A$554,0)),"n.d.") -> 84.638981 | J47: =IFERROR(INDEX('Referência'!$H$2:$H$554,MATCH($B$4&"|"&J$8&"|pre_natal_7mais",'Referência'!$A$2:$A$554,0)),"n.d.") -> 85.893278 | ... M47: =IFERROR(INDEX('Referência'!$H$2:$H$554,MATCH($B$4&"|"&M$8&"|pre_natal_7mais",'Referência'!$A$2:$A$554,0)),"n.d.") -> n.d.
B48: 1º quartil da faixa | C48: =IFERROR(INDEX('Referência'!$G$2:$G$554,MATCH($B$4&"|"&C$8&"|pre_natal_7mais",'Referência'!$A$2:$A$554,0)),"n.d.") -> 76.287388 | D48: =IFERROR(INDEX('Referência'!$G$2:$G$554,MATCH($B$4&"|"&D$8&"|pre_natal_7mais",'Referência'!$A$2:$A$554,0)),"n.d.") -> 76.564456 | E48: =IFERROR(INDEX('Referência'!$G$2:$G$554,MATCH($B$4&"|"&E$8&"|pre_natal_7mais",'Referência'!$A$2:$A$554,0)),"n.d.") -> 77.13575 | F48: =IFERROR(INDEX('Referência'!$G$2:$G$554,MATCH($B$4&"|"&F$8&"|pre_natal_7mais",'Referência'!$A$2:$A$554,0)),"n.d.") -> 78.657407 | G48: =IFERROR(INDEX('Referência'!$G$2:$G$554,MATCH($B$4&"|"&G$8&"|pre_natal_7mais",'Referência'!$A$2:$A$554,0)),"n.d.") -> 80.191711 | H48: =IFERROR(INDEX('Referência'!$G$2:$G$554,MATCH($B$4&"|"&H$8&"|pre_natal_7mais",'Referência'!$A$2:$A$554,0)),"n.d.") -> 78.94697 | I48: =IFERROR(INDEX('Referência'!$G$2:$G$554,MATCH($B$4&"|"&I$8&"|pre_natal_7mais",'Referência'!$A$2:$A$554,0)),"n.d.") -> 79.65317 | J48: =IFERROR(INDEX('Referência'!$G$2:$G$554,MATCH($B$4&"|"&J$8&"|pre_natal_7mais",'Referência'!$A$2:$A$554,0)),"n.d.") -> 80.771755 | ... M48: =IFERROR(INDEX('Referência'!$G$2:$G$554,MATCH($B$4&"|"&M$8&"|pre_natal_7mais",'Referência'!$A$2:$A$554,0)),"n.d.") -> n.d.
B49: 3º quartil da faixa | C49: =IFERROR(INDEX('Referência'!$I$2:$I$554,MATCH($B$4&"|"&C$8&"|pre_natal_7mais",'Referência'!$A$2:$A$554,0)),"n.d.") -> 86.956976 | D49: =IFERROR(INDEX('Referência'!$I$2:$I$554,MATCH($B$4&"|"&D$8&"|pre_natal_7mais",'Referência'!$A$2:$A$554,0)),"n.d.") -> 86.946175 | E49: =IFERROR(INDEX('Referência'!$I$2:$I$554,MATCH($B$4&"|"&E$8&"|pre_natal_7mais",'Referência'!$A$2:$A$554,0)),"n.d.") -> 87.55508 | F49: =IFERROR(INDEX('Referência'!$I$2:$I$554,MATCH($B$4&"|"&F$8&"|pre_natal_7mais",'Referência'!$A$2:$A$554,0)),"n.d.") -> 88.699158 | G49: =IFERROR(INDEX('Referência'!$I$2:$I$554,MATCH($B$4&"|"&G$8&"|pre_natal_7mais",'Referência'!$A$2:$A$554,0)),"n.d.") -> 89.147119 | H49: =IFERROR(INDEX('Referência'!$I$2:$I$554,MATCH($B$4&"|"&H$8&"|pre_natal_7mais",'Referência'!$A$2:$A$554,0)),"n.d.") -> 89.596037 | I49: =IFERROR(INDEX('Referência'!$I$2:$I$554,MATCH($B$4&"|"&I$8&"|pre_natal_7mais",'Referência'!$A$2:$A$554,0)),"n.d.") -> 88.975648 | J49: =IFERROR(INDEX('Referência'!$I$2:$I$554,MATCH($B$4&"|"&J$8&"|pre_natal_7mais",'Referência'!$A$2:$A$554,0)),"n.d.") -> 89.271549 | ... M49: =IFERROR(INDEX('Referência'!$I$2:$I$554,MATCH($B$4&"|"&M$8&"|pre_natal_7mais",'Referência'!$A$2:$A$554,0)),"n.d.") -> n.d.
...

Sheet Previsão
A1: Previsão da receita corrente do município
A2: Município (escolhido na aba Painel) | C2: =Painel!$C$4 -> Ibirá
A3: Código IBGE | C3: =Painel!$C$5 -> 3519402
A4: Grupo de porte do modelo | C4: =INDEX('Municípios'!$F$2:$F$646,MATCH($C$2,'Municípios'!$B$2:$B$646,0)) -> B. De 10 a 50 mil
I5: Apoio ao gráfico (não editar)
A6: Ano | B6: Observado (R$ milhões de 2025) | C6: Previsto | D6: Inferior 80% | E6: Superior 80% | F6: Inferior 95% | G6: Superior 95% | I6: Ano | J6: Observado | K6: Previsto | L6: Inf. 80% | M6: Sup. 80% | N6: Inf. 95% | O6: Sup. 95%
A7: 2015 | B7: =IFERROR(INDEX('Dados'!$M$2:$M$7096,MATCH($C$3&"|"&A7,'Dados'!$A$2:$A$7096,0)),"n.d.") -> 59.846729 | I7: =A7 -> 2015 | J7: =IF(ISNUMBER(B7),B7,NA()) -> 59.846729 | K7: =IF(ISNUMBER(C7),C7,NA()) -> #N/A | L7: =IF(ISNUMBER(D7),D7,NA()) -> #N/A | M7: =IF(ISNUMBER(E7),E7,NA()) -> #N/A | N7: =IF(ISNUMBER(F7),F7,NA()) -> #N/A | O7: =IF(ISNUMBER(G7),G7,NA()) -> #N/A
A8: 2016 | B8: =IFERROR(INDEX('Dados'!$M$2:$M$7096,MATCH($C$3&"|"&A8,'Dados'!$A$2:$A$7096,0)),"n.d.") -> 59.176247 | I8: =A8 -> 2016 | J8: =IF(ISNUMBER(B8),B8,NA()) -> 59.176247 | K8: =IF(ISNUMBER(C8),C8,NA()) -> #N/A | L8: =IF(ISNUMBER(D8),D8,NA()) -> #N/A | M8: =IF(ISNUMBER(E8),E8,NA()) -> #N/A | N8: =IF(ISNUMBER(F8),F8,NA()) -> #N/A | O8: =IF(ISNUMBER(G8),G8,NA()) -> #N/A
A9: 2017 | B9: =IFERROR(INDEX('Dados'!$M$2:$M$7096,MATCH($C$3&"|"&A9,'Dados'!$A$2:$A$7096,0)),"n.d.") -> 53.500928 | I9: =A9 -> 2017 | J9: =IF(ISNUMBER(B9),B9,NA()) -> 53.500928 | K9: =IF(ISNUMBER(C9),C9,NA()) -> #N/A | L9: =IF(ISNUMBER(D9),D9,NA()) -> #N/A | M9: =IF(ISNUMBER(E9),E9,NA()) -> #N/A | N9: =IF(ISNUMBER(F9),F9,NA()) -> #N/A | O9: =IF(ISNUMBER(G9),G9,NA()) -> #N/A
A10: 2018 | B10: =IFERROR(INDEX('Dados'!$M$2:$M$7096,MATCH($C$3&"|"&A10,'Dados'!$A$2:$A$7096,0)),"n.d.") -> 54.05821 | I10: =A10 -> 2018 | J10: =IF(ISNUMBER(B10),B10,NA()) -> 54.05821 | K10: =IF(ISNUMBER(C10),C10,NA()) -> #N/A | L10: =IF(ISNUMBER(D10),D10,NA()) -> #N/A | M10: =IF(ISNUMBER(E10),E10,NA()) -> #N/A | N10: =IF(ISNUMBER(F10),F10,NA()) -> #N/A | O10: =IF(ISNUMBER(G10),G10,NA()) -> #N/A
A11: 2019 | B11: =IFERROR(INDEX('Dados'!$M$2:$M$7096,MATCH($C$3&"|"&A11,'Dados'!$A$2:$A$7096,0)),"n.d.") -> 56.139926 | I11: =A11 -> 2019 | J11: =IF(ISNUMBER(B11),B11,NA()) -> 56.139926 | K11: =IF(ISNUMBER(C11),C11,NA()) -> #N/A | L11: =IF(ISNUMBER(D11),D11,NA()) -> #N/A | M11: =IF(ISNUMBER(E11),E11,NA()) -> #N/A | N11: =IF(ISNUMBER(F11),F11,NA()) -> #N/A | O11: =IF(ISNUMBER(G11),G11,NA()) -> #N/A
A12: 2020 | B12: =IFERROR(INDEX('Dados'!$M$2:$M$7096,MATCH($C$3&"|"&A12,'Dados'!$A$2:$A$7096,0)),"n.d.") -> 59.642237 | I12: =A12 -> 2020 | J12: =IF(ISNUMBER(B12),B12,NA()) -> 59.642237 | K12: =IF(ISNUMBER(C12),C12,NA()) -> #N/A | L12: =IF(ISNUMBER(D12),D12,NA()) -> #N/A | M12: =IF(ISNUMBER(E12),E12,NA()) -> #N/A | N12: =IF(ISNUMBER(F12),F12,NA()) -> #N/A | O12: =IF(ISNUMBER(G12),G12,NA()) -> #N/A
A13: 2021 | B13: =IFERROR(INDEX('Dados'!$M$2:$M$7096,MATCH($C$3&"|"&A13,'Dados'!$A$2:$A$7096,0)),"n.d.") -> 61.417603 | I13: =A13 -> 2021 | J13: =IF(ISNUMBER(B13),B13,NA()) -> 61.417603 | K13: =IF(ISNUMBER(C13),C13,NA()) -> #N/A | L13: =IF(ISNUMBER(D13),D13,NA()) -> #N/A | M13: =IF(ISNUMBER(E13),E13,NA()) -> #N/A | N13: =IF(ISNUMBER(F13),F13,NA()) -> #N/A | O13: =IF(ISNUMBER(G13),G13,NA()) -> #N/A
A14: 2022 | B14: =IFERROR(INDEX('Dados'!$M$2:$M$7096,MATCH($C$3&"|"&A14,'Dados'!$A$2:$A$7096,0)),"n.d.") -> 66.300472 | I14: =A14 -> 2022 | J14: =IF(ISNUMBER(B14),B14,NA()) -> 66.300472 | K14: =IF(ISNUMBER(C14),C14,NA()) -> #N/A | L14: =IF(ISNUMBER(D14),D14,NA()) -> #N/A | M14: =IF(ISNUMBER(E14),E14,NA()) -> #N/A | N14: =IF(ISNUMBER(F14),F14,NA()) -> #N/A | O14: =IF(ISNUMBER(G14),G14,NA()) -> #N/A
A15: 2023 | B15: =IFERROR(INDEX('Dados'!$M$2:$M$7096,MATCH($C$3&"|"&A15,'Dados'!$A$2:$A$7096,0)),"n.d.") -> 67.017445 | I15: =A15 -> 2023 | J15: =IF(ISNUMBER(B15),B15,NA()) -> 67.017445 | K15: =IF(ISNUMBER(C15),C15,NA()) -> #N/A | L15: =IF(ISNUMBER(D15),D15,NA()) -> #N/A | M15: =IF(ISNUMBER(E15),E15,NA()) -> #N/A | N15: =IF(ISNUMBER(F15),F15,NA()) -> #N/A | O15: =IF(ISNUMBER(G15),G15,NA()) -> #N/A
A16: 2024 | B16: =IFERROR(INDEX('Dados'!$M$2:$M$7096,MATCH($C$3&"|"&A16,'Dados'!$A$2:$A$7096,0)),"n.d.") -> 72.802827 | I16: =A16 -> 2024 | J16: =IF(ISNUMBER(B16),B16,NA()) -> 72.802827 | K16: =IF(ISNUMBER(C16),C16,NA()) -> #N/A | L16: =IF(ISNUMBER(D16),D16,NA()) -> #N/A | M16: =IF(ISNUMBER(E16),E16,NA()) -> #N/A | N16: =IF(ISNUMBER(F16),F16,NA()) -> #N/A | O16: =IF(ISNUMBER(G16),G16,NA()) -> #N/A
A17: 2025 | B17: =IFERROR(INDEX('Dados'!$M$2:$M$7096,MATCH($C$3&"|"&A17,'Dados'!$A$2:$A$7096,0)),"n.d.") -> 76.662255 | C17: =B17 -> 76.662255 | D17: =B17 -> 76.662255 | E17: =B17 -> 76.662255 | F17: =B17 -> 76.662255 | G17: =B17 -> 76.662255 | I17: =A17 -> 2025 | J17: =IF(ISNUMBER(B17),B17,NA()) -> 76.662255 | K17: =IF(ISNUMBER(C17),C17,NA()) -> 76.662255 | L17: =IF(ISNUMBER(D17),D17,NA()) -> 76.662255 | M17: =IF(ISNUMBER(E17),E17,NA()) -> 76.662255 | N17: =IF(ISNUMBER(F17),F17,NA()) -> 76.662255 | O17: =IF(ISNUMBER(G17),G17,NA()) -> 76.662255
A18: 2026 | C18: =IFERROR(INDEX('Previsões'!$E$2:$E$1927,MATCH($C$3&"|"&A18,'Previsões'!$A$2:$A$1927,0)),"n.d.") -> 80.464301 | D18: =IFERROR(INDEX('Previsões'!$F$2:$F$1927,MATCH($C$3&"|"&A18,'Previsões'!$A$2:$A$1927,0)),"n.d.") -> 72.416588 | E18: =IFERROR(INDEX('Previsões'!$G$2:$G$1927,MATCH($C$3&"|"&A18,'Previsões'!$A$2:$A$1927,0)),"n.d.") -> 91.314098 | F18: =IFERROR(INDEX('Previsões'!$H$2:$H$1927,MATCH($C$3&"|"&A18,'Previsões'!$A$2:$A$1927,0)),"n.d.") -> 67.926121 | G18: =IFERROR(INDEX('Previsões'!$I$2:$I$1927,MATCH($C$3&"|"&A18,'Previsões'!$A$2:$A$1927,0)),"n.d.") -> 98.871653 | I18: =A18 -> 2026 | J18: =IF(ISNUMBER(B18),B18,NA()) -> #N/A | K18: =IF(ISNUMBER(C18),C18,NA()) -> 80.464301 | L18: =IF(ISNUMBER(D18),D18,NA()) -> 72.416588 | M18: =IF(ISNUMBER(E18),E18,NA()) -> 91.314098 | N18: =IF(ISNUMBER(F18),F18,NA()) -> 67.926121 | O18: =IF(ISNUMBER(G18),G18,NA()) -> 98.871653
A19: 2027 | C19: =IFERROR(INDEX('Previsões'!$E$2:$E$1927,MATCH($C$3&"|"&A19,'Previsões'!$A$2:$A$1927,0)),"n.d.") -> 84.454909 | D19: =IFERROR(INDEX('Previsões'!$F$2:$F$1927,MATCH($C$3&"|"&A19,'Previsões'!$A$2:$A$1927,0)),"n.d.") -> 73.781226 | E19: =IFERROR(INDEX('Previsões'!$G$2:$G$1927,MATCH($C$3&"|"&A19,'Previsões'!$A$2:$A$1927,0)),"n.d.") -> 101.68025 | F19: =IFERROR(INDEX('Previsões'!$H$2:$H$1927,MATCH($C$3&"|"&A19,'Previsões'!$A$2:$A$1927,0)),"n.d.") -> 68.188566 | G19: =IFERROR(INDEX('Previsões'!$I$2:$I$1927,MATCH($C$3&"|"&A19,'Previsões'!$A$2:$A$1927,0)),"n.d.") -> 113.02179 | I19: =A19 -> 2027 | J19: =IF(ISNUMBER(B19),B19,NA()) -> #N/A | K19: =IF(ISNUMBER(C19),C19,NA()) -> 84.454909 | L19: =IF(ISNUMBER(D19),D19,NA()) -> 73.781226 | M19: =IF(ISNUMBER(E19),E19,NA()) -> 101.68025 | N19: =IF(ISNUMBER(F19),F19,NA()) -> 68.188566 | O19: =IF(ISNUMBER(G19),G19,NA()) -> 113.02179
A20: 2028 | C20: =IFERROR(INDEX('Previsões'!$E$2:$E$1927,MATCH($C$3&"|"&A20,'Previsões'!$A$2:$A$1927,0)),"n.d.") -> 88.643431 | D20: =IFERROR(INDEX('Previsões'!$F$2:$F$1927,MATCH($C$3&"|"&A20,'Previsões'!$A$2:$A$1927,0)),"n.d.") -> 74.914188 | E20: =IFERROR(INDEX('Previsões'!$G$2:$G$1927,MATCH($C$3&"|"&A20,'Previsões'!$A$2:$A$1927,0)),"n.d.") -> 114.62948 | F20: =IFERROR(INDEX('Previsões'!$H$2:$H$1927,MATCH($C$3&"|"&A20,'Previsões'!$A$2:$A$1927,0)),"n.d.") -> 67.569155 | G20: =IFERROR(INDEX('Previsões'!$I$2:$I$1927,MATCH($C$3&"|"&A20,'Previsões'!$A$2:$A$1927,0)),"n.d.") -> 128.24456 | I20: =A20 -> 2028 | J20: =IF(ISNUMBER(B20),B20,NA()) -> #N/A | K20: =IF(ISNUMBER(C20),C20,NA()) -> 88.643431 | L20: =IF(ISNUMBER(D20),D20,NA()) -> 74.914188 | M20: =IF(ISNUMBER(E20),E20,NA()) -> 114.62948 | N20: =IF(ISNUMBER(F20),F20,NA()) -> 67.569155 | O20: =IF(ISNUMBER(G20),G20,NA()) -> 128.24456
A22: Leitura
A23: =IFERROR("Em 2028, a receita corrente de "&$C$2&" fica perto de R$ "&ROUND(C20,0)&" milhões (a preços de 2025). Na faixa de 80% do teste do passado, entre R$ "&ROUND(D20,0)&" e R$ "&ROUND(E20,0)&" milhões; na de 95%, entre R$ "&ROUND(F20,0)&" e R$ "&ROUND(G20,0)&" milhões.","Este município não tem os cinco últimos anos de receita válidos: sem previsão.") -> Em 2028, a receita corrente de Ibirá fica perto de R$ 89 milhões (a preços de 2025). Na faixa de 80% do teste do passado, entre R$ 75 e R$ 115 milhões; na de 95%, entre R$ 68 e R$ 128 milhões.
A45: Como a previsão foi feita
A46: Série: receita corrente líquida de deduções, em R$ milhões de 2025 (IPCA), de 2015 a 2025. Método escolhido: "tendencia3", sobre o logaritmo da série.
A47: Três métodos simples concorreram: repetir o último valor, estender a tendência dos 3 últimos anos e estender uma reta ajustada aos 5 últimos anos. Cada um foi testado prevendo o passado (origens de 2019 a 2022, 1 a 3 anos à frente) em todos os municípios com série completa; ficou o de menor erro.
A48: A faixa de incerteza não é fórmula de livro: vem dos erros que o método de fato cometeu, por horizonte e por grupo de porte. A receita dos municípios se move junta de um ano para o outro (inflação, ICMS, transferências), então os quatro anos de origem do teste são quatro "choques" e não 600 observações independentes. Por isso a faixa foi testada deixando uma origem de fora e alargada (fator 1.25 para a de 80% e 1.15 para a de 95%) até a cobertura do teste chegar ao nível prometido.
A49: Limites: método sem informação de fora da série; não conhece mudança de lei, de convênio ou de gestão. Depois do ajuste, a cobertura ficou perto do nível prometido na média, mas com a origem 2022 de fora a faixa de 80% cobriu bem menos (tabela abaixo): um ano que vem depois de um salto de receita (2022) é mais difícil de prever. A Revisão técnica por estatístico registrado no CONRE ainda não está registrada para esta amostra.
A51: Erro do método, ao prever o passado
A52: Método | B52: Anos à frente | C52: Previsões testadas | D52: Erro médio absoluto (%) | E52: Viés (%) | F52: Escolhido
A53: ingenuo | B53: 1 | C53: 2516 | D53: 7.0078913 | E53: 5.5525611
A54: ingenuo | B54: 2 | C54: 2516 | D54: 12.668407 | E54: 12.201162
A55: ingenuo | B55: 3 | C55: 2516 | D55: 18.431049 | E55: 18.22658
A56: tendencia3 | B56: 1 | C56: 2516 | D56: 6.5905132 | E56: 1.1940533 | F56: sim
A57: tendencia3 | B57: 2 | C57: 2516 | D57: 9.3520359 | E57: 3.4841463 | F57: sim
A58: tendencia3 | B58: 3 | C58: 2516 | D58: 12.532697 | E58: 5.1510564 | F58: sim
A59: tendencia5 | B59: 1 | C59: 2516 | D59: 6.8462125 | E59: 3.652036
A60: tendencia5 | B60: 2 | C60: 2516 | D60: 9.9990164 | E60: 6.6751016
A61: tendencia5 | B61: 3 | C61: 2516 | D61: 13.267662 | E61: 9.0749844
A63: Quanto da realidade caiu dentro da faixa, deixando uma origem de fora
A64: Nível da faixa (%) | B64: Origem que ficou de fora | C64: Valores testados | D64: Dentro, sem ajuste (%) | E64: Dentro, com ajuste (%)
...

Sheet Indicadores
A1: Indicadores: definição escrita
A2: Cada Indicador tem fórmula, fonte, periodicidade e meta escritas. Sem isso, dois analistas calculam números diferentes com o mesmo nome.
A4: Indicador | B4: Unidade | C4: Fórmula | D4: Fonte | E4: Periodicidade | F4: Meta | G4: Leitura de apoio
A5: Receita corrente por habitante | B5: R$ por habitante, a preços de 2025 | C5: (receitas correntes brutas realizadas − dedução do Fundeb − outras deduções) ÷ população, deflacionado pelo IPCA para a média de 2025 | D5: Siconfi/Tesouro Nacional, DCA Anexo I-C; população do mesmo registro (IBGE); IPCA do IBGE (SIDRA 1737) | E5: Anual | F5: Sem meta nesta amostra: o município a define na lei orçamentária | G5: Mais ou menos depende da escolha do município; não é acerto nem erro.
A6: Dependência de transferências | B6: % da receita corrente | C6: transferências correntes brutas realizadas ÷ receitas correntes brutas realizadas × 100 | D6: Siconfi/Tesouro Nacional, DCA Anexo I-C | E6: Anual | F6: Sem meta nesta amostra | G6: Mais ou menos depende da escolha do município; não é acerto nem erro.
A7: Despesa com saúde por habitante | B7: R$ por habitante, a preços de 2025 | C7: despesa empenhada na função 10 (Saúde) ÷ população, deflacionada pelo IPCA para a média de 2025 | D7: Siconfi/Tesouro Nacional, DCA Anexo I-E; população do mesmo registro (IBGE); IPCA do IBGE | E7: Anual | F7: Sem meta nesta amostra (o piso constitucional é medido sobre a receita de impostos, outro indicador) | G7: Mais ou menos depende da escolha do município; não é acerto nem erro.
A8: Despesa com educação por habitante | B8: R$ por habitante, a preços de 2025 | C8: despesa empenhada na função 12 (Educação) ÷ população, deflacionada pelo IPCA para a média de 2025 | D8: Siconfi/Tesouro Nacional, DCA Anexo I-E; população do mesmo registro (IBGE); IPCA do IBGE | E8: Anual | F8: Sem meta nesta amostra (o piso constitucional é medido sobre a receita de impostos, outro indicador) | G8: Mais ou menos depende da escolha do município; não é acerto nem erro.
A9: PIB por habitante | B9: R$ por habitante, a preços de 2025 | C9: PIB municipal a preços correntes × 1.000 ÷ população, deflacionado pelo IPCA para a média de 2025 | D9: IBGE, Produto Interno Bruto dos Municípios (SIDRA 5938); população do Siconfi (IBGE); IPCA do IBGE | E9: Anual, com defasagem de dois anos (último ano publicado: 2023) | F9: Sem meta | G9: Valor maior costuma indicar situação mais favorável, mas leia com o contexto.
A10: Ideb dos anos iniciais, rede municipal | B10: nota de 0 a 10 | C10: Ideb observado (fluxo escolar × desempenho no Saeb), 1º ao 5º ano, escolas da rede municipal | D10: INEP, Ideb 2023, divulgação por município | E10: Bienal (2015, 2017, 2019, 2021, 2023) | F10: A meta do Ideb é do INEP e vai até 2021; não entra nesta amostra | G10: Valor maior costuma indicar situação mais favorável, mas leia com o contexto.
A11: Nascidos de mães com 7 ou mais consultas de pré-natal | B11: % dos nascidos vivos com número de consultas informado | C11: nascidos vivos de mães com 7 ou mais consultas de pré-natal ÷ nascidos vivos com o número de consultas informado × 100, pelo município de residência da mãe | D11: SINASC/DataSUS, Declaração de Nascido Vivo (arquivos DNSP, ano de nascimento) | E11: Anual | F11: Sem meta nesta amostra | G11: Valor maior costuma indicar situação mais favorável, mas leia com o contexto.
A12: Receita corrente total | B12: R$ milhões, a preços de 2025 | C12: receitas correntes brutas realizadas − dedução do Fundeb − outras deduções, deflacionado pelo IPCA para a média de 2025 | D12: Siconfi/Tesouro Nacional, DCA Anexo I-C; IPCA do IBGE (SIDRA 1737) | E12: Anual | F12: Sem meta nesta amostra. É a série que o modelo de previsão usa, porque não depende da população | G12: Mais ou menos depende da escolha do município; não é acerto nem erro.
